<?xml version="1.0" ?>
<!-- =================================================================================== -->
<!-- |    This document was autogenerated by xacro from schunk_arm_urdf.xacro          | -->
<!-- |    EDITING THIS FILE BY HAND IS NOT RECOMMENDED                                 | -->
<!-- =================================================================================== -->
<robot name="ur10" xmlns:xacro="http://www.ros.org/wiki/xacro">
  <!-- Create fixed base link -->
  <link name="base_link"/>
  <!-- joint between base_link and lwa4p_extended_connector_link -->
  <joint name="lwa4_base_joint" type="fixed">
    <origin>
      <pose rpy="-1.5708 0 0" xyz="0 0 1.02"/>
    </origin>
    <parent link="base_link"/>
    <child link="lwa4_base_link"/>
  </joint>
  <link name="lwa4_base_link">
    <inertial>
      <mass value="0.01"/>
      <origin xyz="0 0 0"/>
      <inertia ixx="0.001" ixy="0.0" ixz="0.0" iyy="0.001" iyz="0.0" izz="0.001"/>
    </inertial>
  </link>
  <!-- joint between arm_base_link and arm_1_link -->
  <joint name="lwa4_1_joint" type="revolute">
    <origin rpy="0 0 0" xyz="0 0 0"/>
    <parent link="lwa4_base_link"/>
    <child link="lwa4_1_link"/>
    <axis xyz="0 0 -1"/>
    <limit effort="216" lower="-3.12159265359" upper="3.12159265359" velocity="0.43633"/>
  </joint>
  <link name="lwa4_1_link">
    <inertial>
      <mass value="0.01"/>
      <origin xyz="0 0 0"/>
      <inertia ixx="0.001" ixy="0.0" ixz="0.0" iyy="0.001" iyz="0.0" izz="0.001"/>
    </inertial>
    <!--
      <xacro:cylinder_inertial radius="0.06" length="0.150" mass="3.6">
          <origin xyz="0 0 0.02" rpy="0 0 0"/>
      </xacro:cylinder_inertial>
-->
    <visual>
      <geometry>
        <mesh filename="package://schunk_description/meshes/lwa4d/arm_1_link.stl"/>
      </geometry>
      <material name="Schunk/LightGrey"/>
    </visual>
    <collision>
      <geometry>
        <mesh filename="package://schunk_description/meshes/lwa4d/arm_1_link.stl"/>
      </geometry>
    </collision>
  </link>
  <!-- joint between arm_1_link and arm_2_link -->
  <joint name="lwa4_2_joint" type="revolute">
    <origin rpy="-1.57079632679 -1.57079632679 0" xyz="0 0 0.240"/>
    <parent link="lwa4_1_link"/>
    <child link="lwa4_2_link"/>
    <axis xyz="0 0 -1"/>
    <limit effort="216" lower="-2.12" upper="2.12" velocity="0.43633"/>
  </joint>
  <link name="lwa4_2_link">
    <inertial>
      <mass value="0.01"/>
      <origin xyz="0 0 0"/>
      <inertia ixx="0.001" ixy="0.0" ixz="0.0" iyy="0.001" iyz="0.0" izz="0.001"/>
    </inertial>
    <!--
      <xacro:cylinder_inertial radius="0.06" length="0.150" mass="2.0">
        <origin xyz="0 0 0" rpy="0 0 0"/>
      </xacro:cylinder_inertial>
-->
    <visual>
      <geometry>
        <mesh filename="package://schunk_description/meshes/lwa4d/arm_2_link.stl"/>
      </geometry>
      <material name="Schunk/Black"/>
    </visual>
    <collision>
      <geometry>
        <mesh filename="package://schunk_description/meshes/lwa4d/arm_2_link_collision.stl"/>
      </geometry>
    </collision>
  </link>
  <!-- joint between arm_2_link and arm_3_link -->
  <joint name="lwa4_3_joint" type="revolute">
    <origin rpy="1.57079632679 0 1.57079632679" xyz="0 0 0"/>
    <parent link="lwa4_2_link"/>
    <child link="lwa4_3_link"/>
    <axis xyz="0 0 -1"/>
    <limit effort="81.5" lower="-3.12159265359" upper="3.12159265359" velocity="0.4189"/>
  </joint>
  <link name="lwa4_3_link">
    <inertial>
      <mass value="0.01"/>
      <origin xyz="0 0 0"/>
      <inertia ixx="0.001" ixy="0.0" ixz="0.0" iyy="0.001" iyz="0.0" izz="0.001"/>
    </inertial>
    <!--
      <xacro:cylinder_inertial radius="0.06" length="0.2" mass="2.0">
        <origin xyz="0.0 0 -0.2" rpy="0 0 0"/>
      </xacro:cylinder_inertial>
-->
    <visual>
      <geometry>
        <mesh filename="package://schunk_description/meshes/lwa4d/arm_3_link.stl"/>
      </geometry>
      <material name="Schunk/LightGrey"/>
    </visual>
    <collision>
      <geometry>
        <mesh filename="package://schunk_description/meshes/lwa4d/arm_3_link_collision.stl"/>
      </geometry>
    </collision>
  </link>
  <!-- joint between arm_3_link and arm_4_link -->
  <joint name="lwa4_4_joint" type="revolute">
    <origin rpy="-1.57079632679 -1.57079632679 0" xyz="0 0 0.328"/>
    <parent link="lwa4_3_link"/>
    <child link="lwa4_4_link"/>
    <axis xyz="0 0 -1"/>
    <limit effort="81.5" lower="-2.16" upper="2.16" velocity="0.4189"/>
  </joint>
  <link name="lwa4_4_link">
    <inertial>
      <mass value="0.01"/>
      <origin xyz="0 0 0"/>
      <inertia ixx="0.001" ixy="0.0" ixz="0.0" iyy="0.001" iyz="0.0" izz="0.001"/>
    </inertial>
    <!--
      <xacro:cylinder_inertial radius="0.06" length="0.150" mass="1.2">
        <origin xyz="0 0 0" rpy="0 0 0"/>
      </xacro:cylinder_inertial>
-->
    <visual>
      <geometry>
        <mesh filename="package://schunk_description/meshes/lwa4d/arm_4_link.stl"/>
      </geometry>
      <material name="Schunk/Black"/>
    </visual>
    <collision>
      <geometry>
        <mesh filename="package://schunk_description/meshes/lwa4d/arm_4_link_collision.stl"/>
      </geometry>
    </collision>
  </link>
  <!-- joint between arm_4_link and arm_5_link -->
  <joint name="lwa4_5_joint" type="revolute">
    <origin rpy="1.57079632679 0 1.57079632679" xyz="0 0 0"/>
    <parent link="lwa4_4_link"/>
    <child link="lwa4_5_link"/>
    <axis xyz="0 0 -1"/>
    <limit effort="20.7" lower="-3.12159265359" upper="3.12159265359" velocity="0.43633"/>
  </joint>
  <link name="lwa4_5_link">
    <inertial>
      <mass value="0.01"/>
      <origin xyz="0 0 0"/>
      <inertia ixx="0.001" ixy="0.0" ixz="0.0" iyy="0.001" iyz="0.0" izz="0.001"/>
    </inertial>
    <!--
      <xacro:cylinder_inertial radius="0.06" length="0.15" mass="1.2">
        <origin xyz="0 0 -0.18" rpy="0 0 0"/>
      </xacro:cylinder_inertial>
-->
    <visual>
      <geometry>
        <mesh filename="package://schunk_description/meshes/lwa4d/arm_5_link.stl"/>
      </geometry>
      <material name="Schunk/LightGrey"/>
    </visual>
    <collision>
      <geometry>
        <mesh filename="package://schunk_description/meshes/lwa4d/arm_5_link_collision.stl"/>
      </geometry>
    </collision>
  </link>
  <!-- joint between arm_5_link and arm_6_link -->
  <joint name="lwa4_6_joint" type="revolute">
    <origin rpy="-1.57079632679 -1.57079632679 0" xyz="0 0 0.323"/>
    <parent link="lwa4_5_link"/>
    <child link="lwa4_6_link"/>
    <axis xyz="0 0 -1"/>
    <limit effort="15" lower="-2.07" upper="2.07" velocity="1.2566"/>
  </joint>
  <link name="lwa4_6_link">
    <inertial>
      <mass value="0.01"/>
      <origin xyz="0 0 0"/>
      <inertia ixx="0.001" ixy="0.0" ixz="0.0" iyy="0.001" iyz="0.0" izz="0.001"/>
    </inertial>
    <!--
      <xacro:sphere_inertial radius="0.05" mass="1.9">
        <origin xyz="0 0 0" rpy="0 0 0"/>
      </xacro:sphere_inertial>
-->
    <visual>
      <geometry>
        <mesh filename="package://schunk_description/meshes/lwa4d/arm_6_link.stl"/>
      </geometry>
      <material name="Schunk/Black"/>
    </visual>
    <collision>
      <geometry>
        <mesh filename="package://schunk_description/meshes/lwa4d/arm_6_link_collision.stl"/>
      </geometry>
    </collision>
  </link>
  <!-- joint between arm_6_link and arm_7_link -->
  <joint name="lwa4_7_joint" type="revolute">
    <origin rpy="1.57079632679 0 1.57079632679" xyz="0 0 0"/>
    <parent link="lwa4_6_link"/>
    <child link="lwa4_7_link"/>
    <axis xyz="0 0 -1"/>
    <limit effort="15" lower="-2.94" upper="2.94" velocity="1.2566"/>
  </joint>
  <link name="lwa4_7_link">
    <inertial>
      <mass value="0.01"/>
      <origin xyz="0 0 0"/>
      <inertia ixx="0.001" ixy="0.0" ixz="0.0" iyy="0.001" iyz="0.0" izz="0.001"/>
    </inertial>
    <!--
      <xacro:cylinder_inertial radius="0.03" length="0.035" mass="0.05">
        <origin xyz="0 0 0.06" rpy="0 0 0"/>
      </xacro:cylinder_inertial>
-->
    <visual>
      <geometry>
        <mesh filename="package://schunk_description/meshes/lwa4d/arm_7_link.stl"/>
      </geometry>
      <material name="Schunk/LightGrey"/>
    </visual>
    <collision>
      <geometry>
        <mesh filename="package://schunk_description/meshes/lwa4d/arm_7_link.stl"/>
      </geometry>
    </collision>
  </link>
  <joint name="lwa4_ee_joint" type="fixed">
    <origin rpy="0 0 0" xyz="0 0 0.0824"/>
    <parent link="lwa4_7_link"/>
    <child link="lwa4_ee_link"/>
  </joint>
  <link name="lwa4_ee_link">
    <inertial>
      <mass value="0.01"/>
      <origin xyz="0 0 0"/>
      <inertia ixx="0.001" ixy="0.0" ixz="0.0" iyy="0.001" iyz="0.0" izz="0.001"/>
    </inertial>
  </link>
  <gazebo reference="lwa4_base_link">
    <gravity>true</gravity>
    <self_collide>false</self_collide>
    <material value="Schunk/Black"/>
  </gazebo>
  <gazebo reference="lwa4_1_link">
    <gravity>true</gravity>
    <self_collide>false</self_collide>
    <material value="Schunk/LightGrey"/>
  </gazebo>
  <gazebo reference="lwa4_2_link">
    <gravity>true</gravity>
    <self_collide>false</self_collide>
    <material value="Schunk/Black"/>
  </gazebo>
  <gazebo reference="lwa4_3_link">
    <gravity>true</gravity>
    <self_collide>false</self_collide>
    <material value="Schunk/LightGrey"/>
  </gazebo>
  <gazebo reference="lwa4_4_link">
    <gravity>true</gravity>
    <self_collide>false</self_collide>
    <material value="Schunk/Black"/>
  </gazebo>
  <gazebo reference="lwa4_5_link">
    <gravity>true</gravity>
    <self_collide>false</self_collide>
    <material value="Schunk/LightGrey"/>
  </gazebo>
  <gazebo reference="lwa4_6_link">
    <gravity>true</gravity>
    <self_collide>false</self_collide>
    <material value="Schunk/Black"/>
  </gazebo>
  <gazebo reference="lwa4_7_link">
    <gravity>true</gravity>
    <self_collide>false</self_collide>
    <material value="Schunk/LightGrey"/>
  </gazebo>
  <transmission name="lwa4_1_trans">
    <type>transmission_interface/SimpleTransmission</type>
    <joint name="lwa4_1_joint">
      <hardwareInterface>PositionJointInterface</hardwareInterface>
      <hardwareInterface>VelocityJointInterface</hardwareInterface>
      <!--hardwareInterface>EffortJointInterface</hardwareInterface-->
    </joint>
    <actuator name="lwa4_1_motor">
      <mechanicalReduction>1</mechanicalReduction>
    </actuator>
  </transmission>
  <transmission name="lwa4_2_trans">
    <type>transmission_interface/SimpleTransmission</type>
    <joint name="lwa4_2_joint">
      <hardwareInterface>PositionJointInterface</hardwareInterface>
      <hardwareInterface>VelocityJointInterface</hardwareInterface>
      <!--hardwareInterface>EffortJointInterface</hardwareInterface-->
    </joint>
    <actuator name="lwa4_2_motor">
      <mechanicalReduction>1</mechanicalReduction>
    </actuator>
  </transmission>
  <transmission name="lwa4_3_trans">
    <type>transmission_interface/SimpleTransmission</type>
    <joint name="lwa4_3_joint">
      <hardwareInterface>PositionJointInterface</hardwareInterface>
      <hardwareInterface>VelocityJointInterface</hardwareInterface>
      <!--hardwareInterface>EffortJointInterface</hardwareInterface-->
    </joint>
    <actuator name="lwa4_3_motor">
      <mechanicalReduction>1</mechanicalReduction>
    </actuator>
  </transmission>
  <transmission name="lwa4_4_trans">
    <type>transmission_interface/SimpleTransmission</type>
    <joint name="lwa4_4_joint">
      <hardwareInterface>PositionJointInterface</hardwareInterface>
      <hardwareInterface>VelocityJointInterface</hardwareInterface>
      <!--hardwareInterface>EffortJointInterface</hardwareInterface-->
    </joint>
    <actuator name="lwa4_4_motor">
      <mechanicalReduction>1</mechanicalReduction>
    </actuator>
  </transmission>
  <transmission name="lwa4_5_trans">
    <type>transmission_interface/SimpleTransmission</type>
    <joint name="lwa4_5_joint">
      <hardwareInterface>PositionJointInterface</hardwareInterface>
      <hardwareInterface>VelocityJointInterface</hardwareInterface>
      <!--hardwareInterface>EffortJointInterface</hardwareInterface-->
    </joint>
    <actuator name="lwa4_5_motor">
      <mechanicalReduction>1</mechanicalReduction>
    </actuator>
  </transmission>
  <transmission name="lwa4_6_trans">
    <type>transmission_interface/SimpleTransmission</type>
    <joint name="lwa4_6_joint">
      <hardwareInterface>PositionJointInterface</hardwareInterface>
      <hardwareInterface>VelocityJointInterface</hardwareInterface>
      <!--hardwareInterface>EffortJointInterface</hardwareInterface-->
    </joint>
    <actuator name="lwa4_6_motor">
      <mechanicalReduction>1</mechanicalReduction>
    </actuator>
  </transmission>
  <transmission name="lwa4_7_trans">
    <type>transmission_interface/SimpleTransmission</type>
    <joint name="lwa4_7_joint">
      <hardwareInterface>PositionJointInterface</hardwareInterface>
      <hardwareInterface>VelocityJointInterface</hardwareInterface>
      <!--hardwareInterface>EffortJointInterface</hardwareInterface-->
    </joint>
    <actuator name="lwa4_7_motor">
      <mechanicalReduction>1</mechanicalReduction>
    </actuator>
  </transmission>
  <!-- joint between arm_7_link and sdh_palm_link -->
  <joint name="sdh_palm_joint" type="fixed">
    <origin>
      <pose rpy="0 0 0" xyz="0 0 0"/>
    </origin>
    <parent link="lwa4_ee_link"/>
    <child link="sdh_palm_link"/>
  </joint>
  <link name="sdh_palm_link">
    <inertial>
      <mass value="1.0288"/>
      <!-- density 1652.3 kg/m3 adjusted to have final total mass of 1.95 -->
      <origin xyz="0 0 0.0386"/>
      <inertia ixx="0.0011896" ixy="0.0" ixz="0.0" iyy="0.0011889" iyz="0.0" izz="0.0015636"/>
    </inertial>
    <visual>
      <origin rpy="0 0 0" xyz="0 0 0"/>
      <geometry>
        <mesh filename="package://schunk_description/meshes/sdh/palm.stl"/>
      </geometry>
      <material name="Schunk/LightGrey"/>
    </visual>
    <collision>
      <origin rpy="0 0 0" xyz="0 0 0"/>
      <geometry>
        <mesh filename="package://schunk_description/meshes/sdh/palm_collision.stl"/>
      </geometry>
    </collision>
  </link>
  <!-- grasp link -->
  <joint name="sdh_grasp_joint" type="fixed">
    <origin rpy="0 0 0" xyz="0 0 0.15"/>
    <parent link="sdh_palm_link"/>
    <child link="sdh_grasp_link"/>
  </joint>
  <link name="sdh_grasp_link">
    <inertial>
      <mass value="0.01"/>
      <origin xyz="0 0 0"/>
      <inertia ixx="0.001" ixy="0.0" ixz="0.0" iyy="0.001" iyz="0.0" izz="0.001"/>
    </inertial>
    <visual>
      <origin rpy="0 0 0" xyz="0 0 0"/>
      <geometry>
        <box size="0.001 0.001 0.001"/>
      </geometry>
    </visual>
    <collision>
      <origin rpy="0 0 0" xyz="0 0 0"/>
      <geometry>
        <box size="0.001 0.001 0.001"/>
      </geometry>
    </collision>
  </link>
  <!-- tip link -->
  <joint name="sdh_tip_joint" type="fixed">
    <origin rpy="0 0 0" xyz="0 0 0.22"/>
    <parent link="sdh_palm_link"/>
    <child link="sdh_tip_link"/>
  </joint>
  <link name="sdh_tip_link">
    <inertial>
      <mass value="0.01"/>
      <origin xyz="0 0 0"/>
      <inertia ixx="0.001" ixy="0.0" ixz="0.0" iyy="0.001" iyz="0.0" izz="0.001"/>
    </inertial>
    <visual>
      <origin rpy="0 0 0" xyz="0 0 0"/>
      <geometry>
        <box size="0.001 0.001 0.001"/>
      </geometry>
    </visual>
    <collision>
      <origin rpy="0 0 0" xyz="0 0 0"/>
      <geometry>
        <box size="0.001 0.001 0.001"/>
      </geometry>
    </collision>
  </link>
  <!-- finger1 -->
  <!-- joint between sdh_palm_link and sdh_finger_11_link -->
  <joint name="sdh_knuckle_joint" type="revolute">
    <origin rpy="0 0 3.14159265" xyz="0.01905 0.033 0.0745"/>
    <parent link="sdh_palm_link"/>
    <child link="sdh_finger_11_link"/>
    <axis xyz="0 0 1"/>
    <dynamics damping="1"/>
    <limit effort="100" lower="0" upper="1.570796327" velocity="5"/>
  </joint>
  <link name="sdh_finger_11_link">
    <inertial>
      <mass value="0.047"/>
      <!-- density of aluminum -->
      <origin xyz="0.0 2.2105e-03 1.2155e-02"/>
      <inertia ixx="1.5889e-05" ixy="0.0" ixz="0.0" iyy="6.9350e-06" iyz="-4.7500e-07" izz="1.4915e-05"/>
    </inertial>
    <visual>
      <origin rpy="0 0 0" xyz="0 0 0"/>
      <geometry>
        <mesh filename="package://schunk_description/meshes/sdh/knuckle.stl"/>
      </geometry>
      <material name="Schunk/LightGrey"/>
    </visual>
    <collision>
      <origin rpy="0 0 0" xyz="0 0 0"/>
      <geometry>
        <mesh filename="package://schunk_description/meshes/sdh/knuckle_collision.stl"/>
      </geometry>
    </collision>
  </link>
  <!-- joint between sdh_finger_11_link and sdh_finger_12_link -->
  <joint name="sdh_finger_12_joint" type="revolute">
    <origin rpy="0 0 0" xyz="0 0 0.0165"/>
    <parent link="sdh_finger_11_link"/>
    <child link="sdh_finger_12_link"/>
    <axis xyz="0 1 0"/>
    <dynamics damping="1"/>
    <limit effort="100" lower="-1.570796327" upper="1.570796327" velocity="5"/>
  </joint>
  <link name="sdh_finger_12_link">
    <inertial>
      <mass value="0.167"/>
      <!-- density of aluminum -->
      <origin xyz="0.0007467 -0.0000378 0.0430192"/>
      <inertia ixx="1.5920e-04" ixy="0.0" ixz="-2.3750e-08" iyy="1.5903e-04" iyz="9.3100e-06" izz="1.9142e-05"/>
    </inertial>
    <visual>
      <origin rpy="0 0 0" xyz="0 0 0"/>
      <geometry>
        <mesh filename="package://schunk_description/meshes/sdh/finger.stl"/>
      </geometry>
      <material name="Schunk/LightGrey"/>
    </visual>
    <collision>
      <origin rpy="0 0 0" xyz="0 0 0"/>
      <geometry>
        <mesh filename="package://schunk_description/meshes/sdh/finger.stl"/>
      </geometry>
    </collision>
  </link>
  <!-- joint between sdh_finger_12_link and sdh_finger_13_link -->
  <joint name="sdh_finger_13_joint" type="revolute">
    <origin rpy="0 0 0" xyz="0 0 0.0865"/>
    <parent link="sdh_finger_12_link"/>
    <child link="sdh_finger_13_link"/>
    <axis xyz="0 1 0"/>
    <dynamics damping="1"/>
    <limit effort="100" lower="-1.570796327" upper="1.570796327" velocity="5"/>
  </joint>
  <link name="sdh_finger_13_link">
    <inertial>
      <mass value="0.0929"/>
      <!-- density of aluminum -->
      <origin xyz="0.0007467 -0.0000378 0.0430192"/>
      <inertia ixx="4.2323e-05" ixy="1.9000e-07" ixz="-5.2250e-07" iyy="3.9734e-05" iyz="5.7950e-06" izz="1.1210e-05"/>
    </inertial>
    <visual>
      <origin rpy="0 0 0" xyz="0 0 0"/>
      <geometry>
        <mesh filename="package://schunk_description/meshes/sdh/finger_tip.stl"/>
      </geometry>
      <material name="Schunk/LightGrey"/>
    </visual>
    <collision>
      <origin rpy="0 0 0" xyz="0 0 0"/>
      <geometry>
        <mesh filename="package://schunk_description/meshes/sdh/finger_tip.stl"/>
      </geometry>
    </collision>
  </link>
  <!-- finger2 -->
  <!-- joint between sdh_palm_link and sdh_finger_21_link -->
  <joint name="sdh_finger_21_joint" type="revolute">
    <mimic joint="sdh_knuckle_joint" multiplier="1" offset="0"/>
    <origin rpy="0 0 3.14159265" xyz="0.01905 -0.033 0.0745"/>
    <parent link="sdh_palm_link"/>
    <child link="sdh_finger_21_link"/>
    <axis xyz="0 0 -1"/>
    <dynamics damping="1"/>
    <limit effort="100" lower="0" upper="1.570796327" velocity="5"/>
  </joint>
  <link name="sdh_finger_21_link">
    <inertial>
      <mass value="0.047"/>
      <!-- density of aluminum -->
      <origin xyz="0.0 2.2105e-03 1.2155e-02"/>
      <inertia ixx="1.5889e-05" ixy="0.0" ixz="0.0" iyy="6.9350e-06" iyz="-4.7500e-07" izz="1.4915e-05"/>
    </inertial>
    <visual>
      <origin rpy="0 0 0" xyz="0 0 0"/>
      <geometry>
        <mesh filename="package://schunk_description/meshes/sdh/knuckle.stl"/>
      </geometry>
      <material name="Schunk/LightGrey"/>
    </visual>
    <collision>
      <origin rpy="0 0 0" xyz="0 0 0"/>
      <geometry>
        <mesh filename="package://schunk_description/meshes/sdh/knuckle_collision.stl"/>
      </geometry>
    </collision>
  </link>
  <!-- joint between sdh_finger_21_link and sdh_finger_22_link -->
  <joint name="sdh_finger_22_joint" type="revolute">
    <origin rpy="0 0 0" xyz="0 0 0.0165"/>
    <parent link="sdh_finger_21_link"/>
    <child link="sdh_finger_22_link"/>
    <axis xyz="0 1 0"/>
    <dynamics damping="1"/>
    <limit effort="100" lower="-1.570796327" upper="1.570796327" velocity="5"/>
  </joint>
  <link name="sdh_finger_22_link">
    <inertial>
      <mass value="0.167"/>
      <!-- density of aluminum -->
      <origin xyz="0.0007467 -0.0000378 0.0430192"/>
      <inertia ixx="1.5920e-04" ixy="0.0" ixz="-2.3750e-08" iyy="1.5903e-04" iyz="9.3100e-06" izz="1.9142e-05"/>
    </inertial>
    <visual>
      <origin rpy="0 0 0" xyz="0 0 0"/>
      <geometry>
        <mesh filename="package://schunk_description/meshes/sdh/finger.stl"/>
      </geometry>
      <material name="Schunk/LightGrey"/>
    </visual>
    <collision>
      <origin rpy="0 0 0" xyz="0 0 0"/>
      <geometry>
        <mesh filename="package://schunk_description/meshes/sdh/finger.stl"/>
      </geometry>
    </collision>
  </link>
  <!-- joint between sdh_finger_22_link and sdh_finger_23_link -->
  <joint name="sdh_finger_23_joint" type="revolute">
    <origin rpy="0 0 0" xyz="0 0 0.0865"/>
    <parent link="sdh_finger_22_link"/>
    <child link="sdh_finger_23_link"/>
    <axis xyz="0 1 0"/>
    <dynamics damping="1"/>
    <limit effort="100" lower="-1.570796327" upper="1.570796327" velocity="5"/>
  </joint>
  <link name="sdh_finger_23_link">
    <inertial>
      <mass value="0.0929"/>
      <!-- density of aluminum -->
      <origin xyz="0.0007467 -0.0000378 0.0430192"/>
      <inertia ixx="4.2323e-05" ixy="1.9000e-07" ixz="-5.2250e-07" iyy="3.9734e-05" iyz="5.7950e-06" izz="1.1210e-05"/>
    </inertial>
    <visual>
      <origin rpy="0 0 0" xyz="0 0 0"/>
      <geometry>
        <mesh filename="package://schunk_description/meshes/sdh/finger_tip.stl"/>
      </geometry>
      <material name="Schunk/LightGrey"/>
    </visual>
    <collision>
      <origin rpy="0 0 0" xyz="0 0 0"/>
      <geometry>
        <mesh filename="package://schunk_description/meshes/sdh/finger_tip.stl"/>
      </geometry>
    </collision>
  </link>
  <!-- thumb -->
  <!-- joint between sdh_palm_link and sdh_thumb_1_link -->
  <joint name="sdh_thumb_1_joint" type="fixed">
    <origin rpy="0 0 0" xyz="-0.03811 0 0.0745 "/>
    <parent link="sdh_palm_link"/>
    <child link="sdh_thumb_1_link"/>
  </joint>
  <link name="sdh_thumb_1_link">
    <inertial>
      <mass value="0.047"/>
      <!-- density of aluminum -->
      <origin xyz="0.0 2.2105e-03 1.2155e-02"/>
      <inertia ixx="1.5889e-05" ixy="0.0" ixz="0.0" iyy="6.9350e-06" iyz="-4.7500e-07" izz="1.4915e-05"/>
    </inertial>
    <visual>
      <origin rpy="0 0 0" xyz="0 0 0"/>
      <geometry>
        <mesh filename="package://schunk_description/meshes/sdh/knuckle.stl"/>
      </geometry>
      <material name="Schunk/LightGrey"/>
    </visual>
    <collision>
      <origin rpy="0 0 0" xyz="0 0 0"/>
      <geometry>
        <mesh filename="package://schunk_description/meshes/sdh/knuckle_collision.stl"/>
      </geometry>
    </collision>
  </link>
  <!-- joint between sdh_thumb_1_link and shd_thumb_2_link -->
  <joint name="sdh_thumb_2_joint" type="revolute">
    <origin rpy="0 0 0" xyz="0 0 0.0165"/>
    <parent link="sdh_thumb_1_link"/>
    <child link="sdh_thumb_2_link"/>
    <axis xyz="0 1 0"/>
    <dynamics damping="1"/>
    <limit effort="100" lower="-1.570796327" upper="1.570796327" velocity="5"/>
  </joint>
  <link name="sdh_thumb_2_link">
    <inertial>
      <mass value="0.167"/>
      <!-- density of aluminum -->
      <origin xyz="0.0007467 -0.0000378 0.0430192"/>
      <inertia ixx="1.5920e-04" ixy="0.0" ixz="-2.3750e-08" iyy="1.5903e-04" iyz="9.3100e-06" izz="1.9142e-05"/>
    </inertial>
    <visual>
      <origin rpy="0 0 0" xyz="0 0 0"/>
      <geometry>
        <mesh filename="package://schunk_description/meshes/sdh/finger.stl"/>
      </geometry>
      <material name="Schunk/LightGrey"/>
    </visual>
    <collision>
      <origin rpy="0 0 0" xyz="0 0 0"/>
      <geometry>
        <mesh filename="package://schunk_description/meshes/sdh/finger.stl"/>
      </geometry>
    </collision>
  </link>
  <!-- joint between sdh_thumb_2_link and sdh_thumb_3_link -->
  <joint name="sdh_thumb_3_joint" type="revolute">
    <origin rpy="0 0 0" xyz="0 0 0.0865"/>
    <parent link="sdh_thumb_2_link"/>
    <child link="sdh_thumb_3_link"/>
    <axis xyz="0 1 0"/>
    <dynamics damping="1"/>
    <limit effort="100" lower="-1.570796327" upper="1.570796327" velocity="5"/>
  </joint>
  <link name="sdh_thumb_3_link">
    <inertial>
      <mass value="0.0929"/>
      <!-- density of aluminum -->
      <origin xyz="0.0007467 -0.0000378 0.0430192"/>
      <inertia ixx="4.2323e-05" ixy="1.9000e-07" ixz="-5.2250e-07" iyy="3.9734e-05" iyz="5.7950e-06" izz="1.1210e-05"/>
    </inertial>
    <visual>
      <origin rpy="0 0 0" xyz="0 0 0"/>
      <geometry>
        <mesh filename="package://schunk_description/meshes/sdh/finger_tip.stl"/>
      </geometry>
      <material name="Schunk/LightGrey"/>
    </visual>
    <collision>
      <origin rpy="0 0 0" xyz="0 0 0"/>
      <geometry>
        <mesh filename="package://schunk_description/meshes/sdh/finger_tip.stl"/>
      </geometry>
    </collision>
  </link>
  <gazebo reference="sdh_palm_link">
    <gravity>true</gravity>
    <self_collide>false</self_collide>
    <material>Schunk/LightGrey</material>
  </gazebo>
  <gazebo reference="sdh_finger_11_link">
    <gravity>true</gravity>
    <self_collide>false</self_collide>
    <material>Schunk/LightGrey</material>
  </gazebo>
  <gazebo reference="sdh_finger_12_link">
    <gravity>true</gravity>
    <self_collide>false</self_collide>
    <material>Schunk/LightGrey</material>
    <sensor name="sdh_finger_12_contact_sensor" type="contact">
      <always_on>true</always_on>
      <update_rate>100</update_rate>
      <contact>
        <collision>sdh_finger_12_link_collision</collision>
        <topic>sdh_finger_12_bumper</topic>
      </contact>
      <plugin filename="libgazebo_ros_bumper.so" name="sdh_finger_12_gazebo_ros_bumper_controller">
        <frameName>sdh_finger_12_link</frameName>
        <bumperTopicName>sdh_finger_12_bumper</bumperTopicName>
      </plugin>
    </sensor>
  </gazebo>
  <gazebo reference="sdh_finger_13_link">
    <gravity>true</gravity>
    <self_collide>false</self_collide>
    <material>Schunk/LightGrey</material>
    <sensor name="sdh_finger_13_contact_sensor" type="contact">
      <always_on>true</always_on>
      <update_rate>100</update_rate>
      <contact>
        <collision>sdh_finger_13_link_collision</collision>
        <topic>sdh_finger_13_bumper</topic>
      </contact>
      <plugin filename="libgazebo_ros_bumper.so" name="sdh_finger_13_gazebo_ros_bumper_controller">
        <frameName>sdh_finger_13_link</frameName>
        <bumperTopicName>sdh_finger_13_bumper</bumperTopicName>
      </plugin>
    </sensor>
  </gazebo>
  <gazebo reference="sdh_finger_21_link">
    <gravity>true</gravity>
    <self_collide>false</self_collide>
    <material>Schunk/LightGrey</material>
  </gazebo>
  <gazebo reference="sdh_finger_22_link">
    <gravity>true</gravity>
    <self_collide>false</self_collide>
    <material>Schunk/LightGrey</material>
    <sensor name="sdh_finger_22_contact_sensor" type="contact">
      <always_on>true</always_on>
      <update_rate>100</update_rate>
      <contact>
        <collision>sdh_finger_22_link_collision</collision>
        <topic>sdh_finger_22_bumper</topic>
      </contact>
      <plugin filename="libgazebo_ros_bumper.so" name="sdh_finger_22_gazebo_ros_bumper_controller">
        <frameName>sdh_finger_22_link</frameName>
        <bumperTopicName>sdh_finger_22_bumper</bumperTopicName>
      </plugin>
    </sensor>
  </gazebo>
  <gazebo reference="sdh_finger_23_link">
    <gravity>true</gravity>
    <self_collide>false</self_collide>
    <material>Schunk/LightGrey</material>
    <sensor name="sdh_finger_23_contact_sensor" type="contact">
      <always_on>true</always_on>
      <update_rate>100</update_rate>
      <contact>
        <collision>sdh_finger_23_link_collision</collision>
        <topic>sdh_finger_23_bumper</topic>
      </contact>
      <plugin filename="libgazebo_ros_bumper.so" name="sdh_finger_23_gazebo_ros_bumper_controller">
        <frameName>sdh_finger_23_link</frameName>
        <bumperTopicName>sdh_finger_23_bumper</bumperTopicName>
      </plugin>
    </sensor>
  </gazebo>
  <gazebo reference="sdh_thumb_1_link">
    <gravity>true</gravity>
    <self_collide>false</self_collide>
    <material>Schunk/LightGrey</material>
  </gazebo>
  <gazebo reference="sdh_thumb_2_link">
    <gravity>true</gravity>
    <self_collide>false</self_collide>
    <material>Schunk/LightGrey</material>
    <sensor name="sdh_thumb_2_contact_sensor" type="contact">
      <always_on>true</always_on>
      <update_rate>100</update_rate>
      <contact>
        <collision>sdh_thumb_2_link_collision</collision>
        <topic>sdh_thumb_2_bumper</topic>
      </contact>
      <plugin filename="libgazebo_ros_bumper.so" name="sdh_thumb_2_gazebo_ros_bumper_controller">
        <frameName>sdh_thumb_2_link</frameName>
        <bumperTopicName>sdh_thumb_2_bumper</bumperTopicName>
      </plugin>
    </sensor>
  </gazebo>
  <gazebo reference="sdh_thumb_3_link">
    <gravity>true</gravity>
    <self_collide>false</self_collide>
    <material>Schunk/LightGrey</material>
    <sensor name="sdh_thumb_3_contact_sensor" type="contact">
      <always_on>true</always_on>
      <update_rate>100</update_rate>
      <contact>
        <collision>sdh_thumb_3_link_collision</collision>
        <topic>sdh_thumb_3_bumper</topic>
      </contact>
      <plugin filename="libgazebo_ros_bumper.so" name="sdh_thumb_3_gazebo_ros_bumper_controller">
        <frameName>sdh_thumb_3_link</frameName>
        <bumperTopicName>sdh_thumb_3_bumper</bumperTopicName>
      </plugin>
    </sensor>
  </gazebo>
  <transmission name="sdh_finger_21_trans">
    <type>transmission_interface/SimpleTransmission</type>
    <joint name="sdh_finger_21_joint">
      <hardwareInterface>PositionJointInterface</hardwareInterface>
      <hardwareInterface>VelocityJointInterface</hardwareInterface>
      <!--hardwareInterface>EffortJointInterface</hardwareInterface-->
    </joint>
    <actuator name="sdh_finger_21_motor">
      <mechanicalReduction>1</mechanicalReduction>
    </actuator>
  </transmission>
  <transmission name="sdh_knuckle_trans">
    <type>transmission_interface/SimpleTransmission</type>
    <joint name="sdh_knuckle_joint">
      <hardwareInterface>PositionJointInterface</hardwareInterface>
      <hardwareInterface>VelocityJointInterface</hardwareInterface>
      <!--hardwareInterface>EffortJointInterface</hardwareInterface-->
    </joint>
    <actuator name="sdh_knuckle_motor">
      <mechanicalReduction>1</mechanicalReduction>
    </actuator>
  </transmission>
  <transmission name="sdh_finger_12_trans">
    <type>transmission_interface/SimpleTransmission</type>
    <joint name="sdh_finger_12_joint">
      <hardwareInterface>PositionJointInterface</hardwareInterface>
      <hardwareInterface>VelocityJointInterface</hardwareInterface>
      <!--hardwareInterface>EffortJointInterface</hardwareInterface-->
    </joint>
    <actuator name="sdh_finger_12_motor">
      <mechanicalReduction>1</mechanicalReduction>
    </actuator>
  </transmission>
  <transmission name="sdh_finger_13_trans">
    <type>transmission_interface/SimpleTransmission</type>
    <joint name="sdh_finger_13_joint">
      <hardwareInterface>PositionJointInterface</hardwareInterface>
      <hardwareInterface>VelocityJointInterface</hardwareInterface>
      <!--hardwareInterface>EffortJointInterface</hardwareInterface-->
    </joint>
    <actuator name="sdh_finger_13_motor">
      <mechanicalReduction>1</mechanicalReduction>
    </actuator>
  </transmission>
  <transmission name="sdh_finger_22_trans">
    <type>transmission_interface/SimpleTransmission</type>
    <joint name="sdh_finger_22_joint">
      <hardwareInterface>PositionJointInterface</hardwareInterface>
      <hardwareInterface>VelocityJointInterface</hardwareInterface>
      <!--hardwareInterface>EffortJointInterface</hardwareInterface-->
    </joint>
    <actuator name="sdh_finger_22_motor">
      <mechanicalReduction>1</mechanicalReduction>
    </actuator>
  </transmission>
  <transmission name="sdh_finger_23_trans">
    <type>transmission_interface/SimpleTransmission</type>
    <joint name="sdh_finger_23_joint">
      <hardwareInterface>PositionJointInterface</hardwareInterface>
      <hardwareInterface>VelocityJointInterface</hardwareInterface>
      <!--hardwareInterface>EffortJointInterface</hardwareInterface-->
    </joint>
    <actuator name="sdh_finger_23_motor">
      <mechanicalReduction>1</mechanicalReduction>
    </actuator>
  </transmission>
  <transmission name="sdh_thumb_2_trans">
    <type>transmission_interface/SimpleTransmission</type>
    <joint name="sdh_thumb_2_joint">
      <hardwareInterface>PositionJointInterface</hardwareInterface>
      <hardwareInterface>VelocityJointInterface</hardwareInterface>
      <!--hardwareInterface>EffortJointInterface</hardwareInterface-->
    </joint>
    <actuator name="sdh_thumb_2_motor">
      <mechanicalReduction>1</mechanicalReduction>
    </actuator>
  </transmission>
  <transmission name="sdh_thumb_3_trans">
    <type>transmission_interface/SimpleTransmission</type>
    <joint name="sdh_thumb_3_joint">
      <hardwareInterface>PositionJointInterface</hardwareInterface>
      <hardwareInterface>VelocityJointInterface</hardwareInterface>
      <!--hardwareInterface>EffortJointInterface</hardwareInterface-->
    </joint>
    <actuator name="sdh_thumb_3_motor">
      <mechanicalReduction>1</mechanicalReduction>
    </actuator>
  </transmission>
</robot>

